Workbook
Name KPI_TTF: Exec_Overview!$B$4
Name KPI_FunnelConv: Exec_Overview!$B$6
Name KPI_OpenReqs: Exec_Overview!$B$2
Name KPI_HCvsPlan: Exec_Overview!$B$7
Name KPI_OfferAccept: Exec_Overview!$B$5
Name KPI_Hires: Exec_Overview!$B$3

Sheet Recruiting_Data
A1: Candidate_ID | B1: Requisition_ID | C1: Team | D1: Department | E1: Region | F1: Recruiter | G1: Hiring_Manager | H1: Source_of_Hire | I1: Candidate_Type | J1: Application_Date | K1: Phone_Screen_Date | L1: Onsite_Date | M1: Offer_Date | N1: Hire_Date | O1: Current_Stage | P1: Req_Open_Date | Q1: Time_to_Fill | R1: Headcount_Status
A2: C-10001 | B2: REQ-2026-0036 | C2: Data Science | D2: Engineering | E2: EMEA | F2: Alice Smith | G2: Manager 17 | H2: LinkedIn | I2: Internal | J2: 46105 | K2: 46112 | L2: 46126 | M2: 46136 | N2: 46160 | O2: Hired | P2: 46102 | Q2: 58 | R2: Filled
A3: C-10002 | B3: REQ-2026-0008 | C3: Frontend | D3: Engineering | E3: EMEA | F3: Bob Jones | G3: Manager 18 | H3: University | I3: External | J3: 46123 | K3: 46126 | O3: Screen | P3: 46122 | R3: Filled
A4: C-10003 | B4: REQ-2026-0046 | C4: Data Science | D4: Engineering | E4: NA | F4: Diana Prince | G4: Manager 10 | H4: Job Board | I4: Internal | J4: 46093 | K4: 46097 | L4: 46106 | O4: Onsite | P4: 46093 | R4: Open
A5: C-10004 | B5: REQ-2026-0046 | C5: Data Science | D5: Engineering | E5: LATAM | F5: Charlie Brown | G5: Manager 18 | H5: LinkedIn | I5: Internal | J5: 46042 | K5: 46048 | L5: 46062 | O5: Onsite | P5: 46041 | R5: Open
A6: C-10005 | B6: REQ-2026-0010 | C6: Backend | D6: Engineering | E6: APAC | F6: Diana Prince | G6: Manager 10 | H6: Referral | I6: Referral | J6: 46110 | O6: Withdrawn | P6: 46105 | R6: Filled
A7: C-10006 | B7: REQ-2026-0012 | C7: Marketing | D7: Marketing | E7: APAC | F7: Alice Smith | G7: Manager 11 | H7: Agency | I7: External | J7: 46135 | K7: 46139 | O7: Withdrawn | P7: 46133 | R7: Filled
A8: C-10007 | B8: REQ-2026-0016 | C8: Frontend | D8: Engineering | E8: LATAM | F8: Diana Prince | G8: Manager 13 | H8: LinkedIn | I8: Internal | J8: 46115 | K8: 46120 | O8: Screen | P8: 46113 | R8: Open
A9: C-10008 | B9: REQ-2026-0010 | C9: Sales | D9: Sales | E9: APAC | F9: Bob Jones | G9: Manager 12 | H9: Job Board | I9: External | J9: 46160 | K9: 46166 | L9: 46176 | M9: 46186 | N9: 46209 | O9: Hired | P9: 46156 | Q9: 53 | R9: Filled
A10: C-10009 | B10: REQ-2026-0004 | C10: Sales | D10: Sales | E10: EMEA | F10: Diana Prince | G10: Manager 11 | H10: Referral | I10: Referral | J10: 46098 | K10: 46103 | L10: 46114 | M10: 46124 | N10: 46152 | O10: Hired | P10: 46095 | Q10: 57 | R10: Filled
A11: C-1010 | B11: REQ-2026-0034 | C11: Backend | D11: Engineering | E11: LATAM | F11: Charlie Brown | G11: Manager 5 | H11: LinkedIn | I11: External | J11: 46071 | K11: 46076 | L11: 46089 | M11: 46092 | O11: Offer | P11: 46068 | R11: Filled
A12: C-10011 | B12: REQ-2026-0001 | C12: Sales | D12: Sales | E12: EMEA | F12: Alice Smith | G12: Manager 17 | H12: LinkedIn | I12: Internal | J12: 46075 | K12: 46081 | L12: 46095 | M12: 46103 | N12: 46119 | O12: Hired | P12: 46070 | Q12: 49 | R12: Filled
A13: C-10012 | B13: REQ-2026-0023 | C13: Frontend | D13: Engineering | E13: APAC | F13: Diana Prince | G13: Manager 15 | H13: Referral | I13: Referral | J13: 46056 | K13: 46058 | L13: 46068 | M13: 46075 | N13: 46082 | O13: Hired | P13: 46053 | Q13: 29 | R13: Filled
A14: C-10013 | B14: REQ-2026-0017 | C14: Frontend | D14: Engineering | E14: EMEA | F14: Diana Prince | G14: Manager 6 | H14: University | I14: External | J14: 46113 | K14: 46119 | O14: Screen | P14: 46113 | R14: Filled
A15: C-10014 | B15: REQ-2026-0041 | C15: HR | D15: G&A | E15: LATAM | F15: Charlie Brown | G15: Manager 19 | H15: University | I15: External | J15: 46142 | K15: 46148 | L15: 46160 | O15: Onsite | P15: 46138 | R15: Filled
A16: C-10015 | B16: REQ-2026-0029 | C16: Finance | D16: G&A | E16: LATAM | F16: Alice Smith | G16: Manager 16 | H16: Agency | I16: External | J16: 46139 | K16: 46143 | L16: 46150 | O16: Onsite | P16: 46135 | R16: Filled
A17: C-10016 | B17: REQ-2026-0010 | C17: HR | D17: G&A | E17: NA | F17: Alice Smith | G17: Manager 19 | H17: Referral | I17: Referral | J17: 46072 | O17: Withdrawn | P17: 46067 | R17: Filled
A18: C-10017 | B18: REQ-2026-0030 | C18: Marketing | D18: Marketing | E18: NA | F18: Charlie Brown | G18: Manager 16 | H18: Job Board | I18: Internal | J18: 46057 | K18: 46060 | L18: 46066 | M18: 46072 | O18: Offer | P18: 46056 | R18: Filled
A19: C-10018 | B19: REQ-2026-0030 | C19: Frontend | D19: Engineering | E19: LATAM | F19: Diana Prince | G19: Manager 2 | H19: Agency | I19: External | J19: 46170 | K19: 46176 | L19: 46181 | O19: Onsite | P19: 46165 | R19: Filled
A20: C-10019 | B20: REQ-2026-0044 | C20: Data Science | D20: Engineering | E20: EMEA | F20: Diana Prince | G20: Manager 7 | H20: LinkedIn | I20: Internal | J20: 46072 | K20: 46074 | L20: 46088 | M20: 46092 | N20: 46106 | O20: Hired | P20: 46071 | Q20: 35 | R20: Filled
A21: C-10020 | B21: REQ-2026-0023 | C21: Sales | D21: Sales | E21: LATAM | F21: Alice Smith | G21: Manager 2 | H21: Job Board | I21: Internal | J21: 46041 | O21: Rejected | P21: 46041 | R21: Filled
A22: C-10021 | B22: REQ-2026-0046 | C22: Frontend | D22: Engineering | E22: NA | F22: Diana Prince | G22: Manager 9 | H22: Referral | I22: Referral | J22: 46077 | K22: 46081 | L22: 46088 | O22: Onsite | P22: 46074 | R22: Open
A23: C-10022 | B23: REQ-2026-0029 | C23: Marketing | D23: Marketing | E23: LATAM | F23: Charlie Brown | G23: Manager 9 | H23: LinkedIn | I23: External | J23: 46047 | K23: 46054 | L23: 46068 | M23: 46073 | N23: 46099 | O23: Hired | P23: 46045 | Q23: 54 | R23: Filled
A24: C-10023 | B24: REQ-2026-0030 | C24: Backend | D24: Engineering | E24: APAC | F24: Diana Prince | G24: Manager 4 | H24: Referral | I24: Referral | J24: 46161 | O24: Rejected | P24: 46156 | R24: Filled
A25: C-10024 | B25: REQ-2026-0046 | C25: Sales | D25: Sales | E25: APAC | F25: Alice Smith | G25: Manager 9 | H25: Job Board | I25: External | J25: 46083 | K25: 46090 | O25: Withdrawn | P25: 46078 | R25: Open
A26: C-10025 | B26: REQ-2026-0043 | C26: Marketing | D26: Marketing | E26: EMEA | F26: Charlie Brown | G26: Manager 13 | H26: Agency | I26: Internal | J26: 46067 | K26: 46074 | O26: Screen | P26: 46064 | R26: Open
A27: C-10026 | B27: REQ-2026-0036 | C27: Frontend | D27: Engineering | E27: LATAM | F27: Diana Prince | G27: Manager 16 | H27: University | I27: Internal | J27: 46161 | K27: 46167 | L27: 46176 | O27: Onsite | P27: 46157 | R27: Filled
A28: C-10027 | B28: REQ-2026-0032 | C28: Marketing | D28: Marketing | E28: EMEA | F28: Charlie Brown | G28: Manager 19 | H28: Job Board | I28: External | J28: 46069 | K28: 46074 | L28: 46085 | M28: 46094 | O28: Offer | P28: 46068 | R28: Open
A29: C-10028 | B29: REQ-2026-0031 | C29: Product | D29: Product | E29: LATAM | F29: Alice Smith | G29: Manager 20 | H29: University | I29: Internal | J29: 46024 | K29: 46031 | L29: 46039 | M29: 46044 | O29: Rejected | P29: 46023 | R29: Open
A30: C-10029 | B30: REQ-2026-0050 | C30: Finance | D30: G&A | E30: NA | F30: Diana Prince | G30: Manager 11 | H30: Referral | I30: Referral | J30: 46093 | K30: 46095 | L30: 46105 | O30: Rejected | P30: 46091 | R30: Filled
A31: C-10030 | B31: REQ-2026-0042 | C31: Backend | D31: Engineering | E31: LATAM | F31: Diana Prince | G31: Manager 20 | H31: Agency | I31: External | J31: 46067 | K31: 46072 | L31: 46077 | O31: Onsite | P31: 46066 | R31: Filled
A32: C-10031 | B32: REQ-2026-0032 | C32: Frontend | D32: Engineering | E32: EMEA | F32: Diana Prince | G32: Manager 8 | H32: Agency | I32: Internal | J32: 46121 | K32: 46127 | O32: Withdrawn | P32: 46116 | R32: Open
A33: C-10032 | B33: REQ-2026-0031 | C33: Backend | D33: Engineering | E33: NA | F33: Bob Jones | G33: Manager 10 | H33: Job Board | I33: Internal | J33: 46174 | O33: Rejected | P33: 46171 | R33: Open
A34: C-10033 | B34: REQ-2026-0045 | C34: Frontend | D34: Engineering | E34: NA | F34: Bob Jones | G34: Manager 12 | H34: Referral | I34: Referral | J34: 46073 | K34: 46078 | L34: 46082 | O34: Withdrawn | P34: 46072 | R34: Filled
A35: C-10034 | B35: REQ-2026-0035 | C35: Data Science | D35: Engineering | E35: LATAM | F35: Bob Jones | G35: Manager 2 | H35: LinkedIn | I35: External | J35: 46090 | K35: 46094 | L35: 46106 | O35: Withdrawn | P35: 46090 | R35: Filled
A36: C-10035 | B36: REQ-2026-0034 | C36: Backend | D36: Engineering | E36: NA | F36: Charlie Brown | G36: Manager 5 | H36: Job Board | I36: Internal | J36: 46169 | K36: 46174 | O36: Screen | P36: 46164 | R36: Filled
A37: C-10036 | B37: REQ-2026-0031 | C37: Finance | D37: G&A | E37: NA | F37: Alice Smith | G37: Manager 9 | H37: Job Board | I37: External | J37: 46122 | K37: 46126 | O37: Screen | P37: 46117 | R37: Open
A38: C-10037 | B38: REQ-2026-0006 | C38: Frontend | D38: Engineering | E38: APAC | F38: Alice Smith | G38: Manager 8 | H38: LinkedIn | I38: Internal | J38: 46117 | K38: 46123 | L38: 46132 | O38: Onsite | P38: 46117 | R38: Filled
A39: C-10038 | B39: REQ-2026-0046 | C39: HR | D39: G&A | E39: APAC | F39: Charlie Brown | G39: Manager 15 | H39: Agency | I39: Internal | J39: 46117 | K39: 46119 | O39: Withdrawn | P39: 46113 | R39: Open
A40: C-10039 | B40: REQ-2026-0038 | C40: Product | D40: Product | E40: EMEA | F40: Bob Jones | G40: Manager 6 | H40: University | I40: Internal | J40: 46030 | O40: Rejected | P40: 46030 | R40: Filled
...

Sheet Helper_Calcs
A1: Candidate_ID | B1: Requisition_ID | C1: Calculated_Time_To_Fill | D1: {={"Furthest_Stage"; IF(Recruiting_Data!A2:A1000="", "", SWITCH(Recruiting_Data!O2:O1000, "Applied", 1, "Screen", 2, "Phone Screen", 2, "Onsite", 3, "Offer", 4, "Hired", 5, "Rejected", 1, "Withdrawn", 1, ""))}} -> Furthest_Stage | E1: Open_Req_Age | F1: Age_Bucket | G1: Duplicate_Flag | H1: Date_Logic_Flag
A2: =IF(Recruiting_Data!A2="", "", Recruiting_Data!A2) -> C-10001 | B2: =IF(Recruiting_Data!B2="", "", Recruiting_Data!B2) -> REQ-2026-0036 | C2: =IF(AND(ISNUMBER(Recruiting_Data!N2), ISNUMBER(Recruiting_Data!P2)), Recruiting_Data!N2 - Recruiting_Data!P2, "") -> 58 | D2: 5 | E2: =IF(Recruiting_Data!R2="Open", TODAY() - Recruiting_Data!P2, "") | F2: =IF(E2="", "", IF(E2<=30, "0-30", IF(E2<=60, "31-60", "60+"))) | G2: =IF(A2="", "", IF(COUNTIF(Recruiting_Data!A:A, A2)>1, TRUE, FALSE)) -> FALSE | H2: =IF(A2="", "", IF(OR(AND(Recruiting_Data!N2<>"", Recruiting_Data!J2<>"", Recruiting_Data!N2<Recruiting_Data!J2), AND(Recruiting_Data!M2<>"", Recruiting_Data!L2<>"", Recruiting_Data!M2<Recruiting_Data!L2), AND(Recruiting_Data!L2<>"", Recruiting_Data!K2<>"", Recruiting_Data!L2<Recruiting_Data!K2)), TRUE, FALSE)) -> FALSE
A3: =IF(Recruiting_Data!A3="", "", Recruiting_Data!A3) -> C-10002 | B3: =IF(Recruiting_Data!B3="", "", Recruiting_Data!B3) -> REQ-2026-0008 | C3: =IF(AND(ISNUMBER(Recruiting_Data!N3), ISNUMBER(Recruiting_Data!P3)), Recruiting_Data!N3 - Recruiting_Data!P3, "") | D3: 2 | E3: =IF(Recruiting_Data!R3="Open", TODAY() - Recruiting_Data!P3, "") | F3: =IF(E3="", "", IF(E3<=30, "0-30", IF(E3<=60, "31-60", "60+"))) | G3: =IF(A3="", "", IF(COUNTIF(Recruiting_Data!A:A, A3)>1, TRUE, FALSE)) -> FALSE | H3: =IF(A3="", "", IF(OR(AND(Recruiting_Data!N3<>"", Recruiting_Data!J3<>"", Recruiting_Data!N3<Recruiting_Data!J3), AND(Recruiting_Data!M3<>"", Recruiting_Data!L3<>"", Recruiting_Data!M3<Recruiting_Data!L3), AND(Recruiting_Data!L3<>"", Recruiting_Data!K3<>"", Recruiting_Data!L3<Recruiting_Data!K3)), TRUE, FALSE)) -> FALSE
A4: =IF(Recruiting_Data!A4="", "", Recruiting_Data!A4) -> C-10003 | B4: =IF(Recruiting_Data!B4="", "", Recruiting_Data!B4) -> REQ-2026-0046 | C4: =IF(AND(ISNUMBER(Recruiting_Data!N4), ISNUMBER(Recruiting_Data!P4)), Recruiting_Data!N4 - Recruiting_Data!P4, "") | D4: 3 | E4: =IF(Recruiting_Data!R4="Open", TODAY() - Recruiting_Data!P4, "") -> 186 | F4: =IF(E4="", "", IF(E4<=30, "0-30", IF(E4<=60, "31-60", "60+"))) -> 60+ | G4: =IF(A4="", "", IF(COUNTIF(Recruiting_Data!A:A, A4)>1, TRUE, FALSE)) -> FALSE | H4: =IF(A4="", "", IF(OR(AND(Recruiting_Data!N4<>"", Recruiting_Data!J4<>"", Recruiting_Data!N4<Recruiting_Data!J4), AND(Recruiting_Data!M4<>"", Recruiting_Data!L4<>"", Recruiting_Data!M4<Recruiting_Data!L4), AND(Recruiting_Data!L4<>"", Recruiting_Data!K4<>"", Recruiting_Data!L4<Recruiting_Data!K4)), TRUE, FALSE)) -> FALSE
A5: =IF(Recruiting_Data!A5="", "", Recruiting_Data!A5) -> C-10004 | B5: =IF(Recruiting_Data!B5="", "", Recruiting_Data!B5) -> REQ-2026-0046 | C5: =IF(AND(ISNUMBER(Recruiting_Data!N5), ISNUMBER(Recruiting_Data!P5)), Recruiting_Data!N5 - Recruiting_Data!P5, "") | D5: 3 | E5: =IF(Recruiting_Data!R5="Open", TODAY() - Recruiting_Data!P5, "") -> 238 | F5: =IF(E5="", "", IF(E5<=30, "0-30", IF(E5<=60, "31-60", "60+"))) -> 60+ | G5: =IF(A5="", "", IF(COUNTIF(Recruiting_Data!A:A, A5)>1, TRUE, FALSE)) -> FALSE | H5: =IF(A5="", "", IF(OR(AND(Recruiting_Data!N5<>"", Recruiting_Data!J5<>"", Recruiting_Data!N5<Recruiting_Data!J5), AND(Recruiting_Data!M5<>"", Recruiting_Data!L5<>"", Recruiting_Data!M5<Recruiting_Data!L5), AND(Recruiting_Data!L5<>"", Recruiting_Data!K5<>"", Recruiting_Data!L5<Recruiting_Data!K5)), TRUE, FALSE)) -> FALSE
A6: =IF(Recruiting_Data!A6="", "", Recruiting_Data!A6) -> C-10005 | B6: =IF(Recruiting_Data!B6="", "", Recruiting_Data!B6) -> REQ-2026-0010 | C6: =IF(AND(ISNUMBER(Recruiting_Data!N6), ISNUMBER(Recruiting_Data!P6)), Recruiting_Data!N6 - Recruiting_Data!P6, "") | D6: 1 | E6: =IF(Recruiting_Data!R6="Open", TODAY() - Recruiting_Data!P6, "") | F6: =IF(E6="", "", IF(E6<=30, "0-30", IF(E6<=60, "31-60", "60+"))) | G6: =IF(A6="", "", IF(COUNTIF(Recruiting_Data!A:A, A6)>1, TRUE, FALSE)) -> FALSE | H6: =IF(A6="", "", IF(OR(AND(Recruiting_Data!N6<>"", Recruiting_Data!J6<>"", Recruiting_Data!N6<Recruiting_Data!J6), AND(Recruiting_Data!M6<>"", Recruiting_Data!L6<>"", Recruiting_Data!M6<Recruiting_Data!L6), AND(Recruiting_Data!L6<>"", Recruiting_Data!K6<>"", Recruiting_Data!L6<Recruiting_Data!K6)), TRUE, FALSE)) -> FALSE
A7: =IF(Recruiting_Data!A7="", "", Recruiting_Data!A7) -> C-10006 | B7: =IF(Recruiting_Data!B7="", "", Recruiting_Data!B7) -> REQ-2026-0012 | C7: =IF(AND(ISNUMBER(Recruiting_Data!N7), ISNUMBER(Recruiting_Data!P7)), Recruiting_Data!N7 - Recruiting_Data!P7, "") | D7: 1 | E7: =IF(Recruiting_Data!R7="Open", TODAY() - Recruiting_Data!P7, "") | F7: =IF(E7="", "", IF(E7<=30, "0-30", IF(E7<=60, "31-60", "60+"))) | G7: =IF(A7="", "", IF(COUNTIF(Recruiting_Data!A:A, A7)>1, TRUE, FALSE)) -> FALSE | H7: =IF(A7="", "", IF(OR(AND(Recruiting_Data!N7<>"", Recruiting_Data!J7<>"", Recruiting_Data!N7<Recruiting_Data!J7), AND(Recruiting_Data!M7<>"", Recruiting_Data!L7<>"", Recruiting_Data!M7<Recruiting_Data!L7), AND(Recruiting_Data!L7<>"", Recruiting_Data!K7<>"", Recruiting_Data!L7<Recruiting_Data!K7)), TRUE, FALSE)) -> FALSE
A8: =IF(Recruiting_Data!A8="", "", Recruiting_Data!A8) -> C-10007 | B8: =IF(Recruiting_Data!B8="", "", Recruiting_Data!B8) -> REQ-2026-0016 | C8: =IF(AND(ISNUMBER(Recruiting_Data!N8), ISNUMBER(Recruiting_Data!P8)), Recruiting_Data!N8 - Recruiting_Data!P8, "") | D8: 2 | E8: =IF(Recruiting_Data!R8="Open", TODAY() - Recruiting_Data!P8, "") -> 166 | F8: =IF(E8="", "", IF(E8<=30, "0-30", IF(E8<=60, "31-60", "60+"))) -> 60+ | G8: =IF(A8="", "", IF(COUNTIF(Recruiting_Data!A:A, A8)>1, TRUE, FALSE)) -> FALSE | H8: =IF(A8="", "", IF(OR(AND(Recruiting_Data!N8<>"", Recruiting_Data!J8<>"", Recruiting_Data!N8<Recruiting_Data!J8), AND(Recruiting_Data!M8<>"", Recruiting_Data!L8<>"", Recruiting_Data!M8<Recruiting_Data!L8), AND(Recruiting_Data!L8<>"", Recruiting_Data!K8<>"", Recruiting_Data!L8<Recruiting_Data!K8)), TRUE, FALSE)) -> FALSE
A9: =IF(Recruiting_Data!A9="", "", Recruiting_Data!A9) -> C-10008 | B9: =IF(Recruiting_Data!B9="", "", Recruiting_Data!B9) -> REQ-2026-0010 | C9: =IF(AND(ISNUMBER(Recruiting_Data!N9), ISNUMBER(Recruiting_Data!P9)), Recruiting_Data!N9 - Recruiting_Data!P9, "") -> 53 | D9: 5 | E9: =IF(Recruiting_Data!R9="Open", TODAY() - Recruiting_Data!P9, "") | F9: =IF(E9="", "", IF(E9<=30, "0-30", IF(E9<=60, "31-60", "60+"))) | G9: =IF(A9="", "", IF(COUNTIF(Recruiting_Data!A:A, A9)>1, TRUE, FALSE)) -> FALSE | H9: =IF(A9="", "", IF(OR(AND(Recruiting_Data!N9<>"", Recruiting_Data!J9<>"", Recruiting_Data!N9<Recruiting_Data!J9), AND(Recruiting_Data!M9<>"", Recruiting_Data!L9<>"", Recruiting_Data!M9<Recruiting_Data!L9), AND(Recruiting_Data!L9<>"", Recruiting_Data!K9<>"", Recruiting_Data!L9<Recruiting_Data!K9)), TRUE, FALSE)) -> FALSE
A10: =IF(Recruiting_Data!A10="", "", Recruiting_Data!A10) -> C-10009 | B10: =IF(Recruiting_Data!B10="", "", Recruiting_Data!B10) -> REQ-2026-0004 | C10: =IF(AND(ISNUMBER(Recruiting_Data!N10), ISNUMBER(Recruiting_Data!P10)), Recruiting_Data!N10 - Recruiting_Data!P10, "") -> 57 | D10: 5 | E10: =IF(Recruiting_Data!R10="Open", TODAY() - Recruiting_Data!P10, "") | F10: =IF(E10="", "", IF(E10<=30, "0-30", IF(E10<=60, "31-60", "60+"))) | G10: =IF(A10="", "", IF(COUNTIF(Recruiting_Data!A:A, A10)>1, TRUE, FALSE)) -> FALSE | H10: =IF(A10="", "", IF(OR(AND(Recruiting_Data!N10<>"", Recruiting_Data!J10<>"", Recruiting_Data!N10<Recruiting_Data!J10), AND(Recruiting_Data!M10<>"", Recruiting_Data!L10<>"", Recruiting_Data!M10<Recruiting_Data!L10), AND(Recruiting_Data!L10<>"", Recruiting_Data!K10<>"", Recruiting_Data!L10<Recruiting_Data!K10)), TRUE, FALSE)) -> FALSE
A11: =IF(Recruiting_Data!A11="", "", Recruiting_Data!A11) -> C-1010 | B11: =IF(Recruiting_Data!B11="", "", Recruiting_Data!B11) -> REQ-2026-0034 | C11: =IF(AND(ISNUMBER(Recruiting_Data!N11), ISNUMBER(Recruiting_Data!P11)), Recruiting_Data!N11 - Recruiting_Data!P11, "") | D11: 4 | E11: =IF(Recruiting_Data!R11="Open", TODAY() - Recruiting_Data!P11, "") | F11: =IF(E11="", "", IF(E11<=30, "0-30", IF(E11<=60, "31-60", "60+"))) | G11: =IF(A11="", "", IF(COUNTIF(Recruiting_Data!A:A, A11)>1, TRUE, FALSE)) -> FALSE | H11: =IF(A11="", "", IF(OR(AND(Recruiting_Data!N11<>"", Recruiting_Data!J11<>"", Recruiting_Data!N11<Recruiting_Data!J11), AND(Recruiting_Data!M11<>"", Recruiting_Data!L11<>"", Recruiting_Data!M11<Recruiting_Data!L11), AND(Recruiting_Data!L11<>"", Recruiting_Data!K11<>"", Recruiting_Data!L11<Recruiting_Data!K11)), TRUE, FALSE)) -> FALSE
A12: =IF(Recruiting_Data!A12="", "", Recruiting_Data!A12) -> C-10011 | B12: =IF(Recruiting_Data!B12="", "", Recruiting_Data!B12) -> REQ-2026-0001 | C12: =IF(AND(ISNUMBER(Recruiting_Data!N12), ISNUMBER(Recruiting_Data!P12)), Recruiting_Data!N12 - Recruiting_Data!P12, "") -> 49 | D12: 5 | E12: =IF(Recruiting_Data!R12="Open", TODAY() - Recruiting_Data!P12, "") | F12: =IF(E12="", "", IF(E12<=30, "0-30", IF(E12<=60, "31-60", "60+"))) | G12: =IF(A12="", "", IF(COUNTIF(Recruiting_Data!A:A, A12)>1, TRUE, FALSE)) -> FALSE | H12: =IF(A12="", "", IF(OR(AND(Recruiting_Data!N12<>"", Recruiting_Data!J12<>"", Recruiting_Data!N12<Recruiting_Data!J12), AND(Recruiting_Data!M12<>"", Recruiting_Data!L12<>"", Recruiting_Data!M12<Recruiting_Data!L12), AND(Recruiting_Data!L12<>"", Recruiting_Data!K12<>"", Recruiting_Data!L12<Recruiting_Data!K12)), TRUE, FALSE)) -> FALSE
A13: =IF(Recruiting_Data!A13="", "", Recruiting_Data!A13) -> C-10012 | B13: =IF(Recruiting_Data!B13="", "", Recruiting_Data!B13) -> REQ-2026-0023 | C13: =IF(AND(ISNUMBER(Recruiting_Data!N13), ISNUMBER(Recruiting_Data!P13)), Recruiting_Data!N13 - Recruiting_Data!P13, "") -> 29 | D13: 5 | E13: =IF(Recruiting_Data!R13="Open", TODAY() - Recruiting_Data!P13, "") | F13: =IF(E13="", "", IF(E13<=30, "0-30", IF(E13<=60, "31-60", "60+"))) | G13: =IF(A13="", "", IF(COUNTIF(Recruiting_Data!A:A, A13)>1, TRUE, FALSE)) -> FALSE | H13: =IF(A13="", "", IF(OR(AND(Recruiting_Data!N13<>"", Recruiting_Data!J13<>"", Recruiting_Data!N13<Recruiting_Data!J13), AND(Recruiting_Data!M13<>"", Recruiting_Data!L13<>"", Recruiting_Data!M13<Recruiting_Data!L13), AND(Recruiting_Data!L13<>"", Recruiting_Data!K13<>"", Recruiting_Data!L13<Recruiting_Data!K13)), TRUE, FALSE)) -> FALSE
... A401: =IF(Recruiting_Data!A401="", "", Recruiting_Data!A401) -> C-10400 | B401: =IF(Recruiting_Data!B401="", "", Recruiting_Data!B401) -> REQ-2026-0003 | C401: =IF(AND(ISNUMBER(Recruiting_Data!N401), ISNUMBER(Recruiting_Data!P401)), Recruiting_Data!N401 - Recruiting_Data!P401, "") | D401: 2 | E401: =IF(Recruiting_Data!R401="Open", TODAY() - Recruiting_Data!P401, "") | F401: =IF(E401="", "", IF(E401<=30, "0-30", IF(E401<=60, "31-60", "60+"))) | G401: =IF(A401="", "", IF(COUNTIF(Recruiting_Data!A:A, A401)>1, TRUE, FALSE)) -> FALSE | H401: =IF(A401="", "", IF(OR(AND(Recruiting_Data!N401<>"", Recruiting_Data!J401<>"", Recruiting_Data!N401<Recruiting_Data!J401), AND(Recruiting_Data!M401<>"", Recruiting_Data!L401<>"", Recruiting_Data!M401<Recruiting_Data!L401), AND(Recruiting_Data!L401<>"", Recruiting_Data!K401<>"", Recruiting_Data!L401<Recruiting_Data!K401)), TRUE, FALSE)) -> FALSE
A402: =IF(Recruiting_Data!A402="", "", Recruiting_Data!A402) | B402: =IF(Recruiting_Data!B402="", "", Recruiting_Data!B402) | C402: =IF(AND(ISNUMBER(Recruiting_Data!N402), ISNUMBER(Recruiting_Data!P402)), Recruiting_Data!N402 - Recruiting_Data!P402, "") | E402: =IF(Recruiting_Data!R402="Open", TODAY() - Recruiting_Data!P402, "") | F402: =IF(E402="", "", IF(E402<=30, "0-30", IF(E402<=60, "31-60", "60+"))) | G402: =IF(A402="", "", IF(COUNTIF(Recruiting_Data!A:A, A402)>1, TRUE, FALSE)) | H402: =IF(A402="", "", IF(OR(AND(Recruiting_Data!N402<>"", Recruiting_Data!J402<>"", Recruiting_Data!N402<Recruiting_Data!J402), AND(Recruiting_Data!M402<>"", Recruiting_Data!L402<>"", Recruiting_Data!M402<Recruiting_Data!L402), AND(Recruiting_Data!L402<>"", Recruiting_Data!K402<>"", Recruiting_Data!L402<Recruiting_Data!K402)), TRUE, FALSE))
A403: =IF(Recruiting_Data!A403="", "", Recruiting_Data!A403) | B403: =IF(Recruiting_Data!B403="", "", Recruiting_Data!B403) | C403: =IF(AND(ISNUMBER(Recruiting_Data!N403), ISNUMBER(Recruiting_Data!P403)), Recruiting_Data!N403 - Recruiting_Data!P403, "") | E403: =IF(Recruiting_Data!R403="Open", TODAY() - Recruiting_Data!P403, "") | F403: =IF(E403="", "", IF(E403<=30, "0-30", IF(E403<=60, "31-60", "60+"))) | G403: =IF(A403="", "", IF(COUNTIF(Recruiting_Data!A:A, A403)>1, TRUE, FALSE)) | H403: =IF(A403="", "", IF(OR(AND(Recruiting_Data!N403<>"", Recruiting_Data!J403<>"", Recruiting_Data!N403<Recruiting_Data!J403), AND(Recruiting_Data!M403<>"", Recruiting_Data!L403<>"", Recruiting_Data!M403<Recruiting_Data!L403), AND(Recruiting_Data!L403<>"", Recruiting_Data!K403<>"", Recruiting_Data!L403<Recruiting_Data!K403)), TRUE, FALSE))
A404: =IF(Recruiting_Data!A404="", "", Recruiting_Data!A404) | B404: =IF(Recruiting_Data!B404="", "", Recruiting_Data!B404) | C404: =IF(AND(ISNUMBER(Recruiting_Data!N404), ISNUMBER(Recruiting_Data!P404)), Recruiting_Data!N404 - Recruiting_Data!P404, "") | E404: =IF(Recruiting_Data!R404="Open", TODAY() - Recruiting_Data!P404, "") | F404: =IF(E404="", "", IF(E404<=30, "0-30", IF(E404<=60, "31-60", "60+"))) | G404: =IF(A404="", "", IF(COUNTIF(Recruiting_Data!A:A, A404)>1, TRUE, FALSE)) | H404: =IF(A404="", "", IF(OR(AND(Recruiting_Data!N404<>"", Recruiting_Data!J404<>"", Recruiting_Data!N404<Recruiting_Data!J404), AND(Recruiting_Data!M404<>"", Recruiting_Data!L404<>"", Recruiting_Data!M404<Recruiting_Data!L404), AND(Recruiting_Data!L404<>"", Recruiting_Data!K404<>"", Recruiting_Data!L404<Recruiting_Data!K404)), TRUE, FALSE))
A405: =IF(Recruiting_Data!A405="", "", Recruiting_Data!A405) | B405: =IF(Recruiting_Data!B405="", "", Recruiting_Data!B405) | C405: =IF(AND(ISNUMBER(Recruiting_Data!N405), ISNUMBER(Recruiting_Data!P405)), Recruiting_Data!N405 - Recruiting_Data!P405, "") | E405: =IF(Recruiting_Data!R405="Open", TODAY() - Recruiting_Data!P405, "") | F405: =IF(E405="", "", IF(E405<=30, "0-30", IF(E405<=60, "31-60", "60+"))) | G405: =IF(A405="", "", IF(COUNTIF(Recruiting_Data!A:A, A405)>1, TRUE, FALSE)) | H405: =IF(A405="", "", IF(OR(AND(Recruiting_Data!N405<>"", Recruiting_Data!J405<>"", Recruiting_Data!N405<Recruiting_Data!J405), AND(Recruiting_Data!M405<>"", Recruiting_Data!L405<>"", Recruiting_Data!M405<Recruiting_Data!L405), AND(Recruiting_Data!L405<>"", Recruiting_Data!K405<>"", Recruiting_Data!L405<Recruiting_Data!K405)), TRUE, FALSE))
A406: =IF(Recruiting_Data!A406="", "", Recruiting_Data!A406) | B406: =IF(Recruiting_Data!B406="", "", Recruiting_Data!B406) | C406: =IF(AND(ISNUMBER(Recruiting_Data!N406), ISNUMBER(Recruiting_Data!P406)), Recruiting_Data!N406 - Recruiting_Data!P406, "") | E406: =IF(Recruiting_Data!R406="Open", TODAY() - Recruiting_Data!P406, "") | F406: =IF(E406="", "", IF(E406<=30, "0-30", IF(E406<=60, "31-60", "60+"))) | G406: =IF(A406="", "", IF(COUNTIF(Recruiting_Data!A:A, A406)>1, TRUE, FALSE)) | H406: =IF(A406="", "", IF(OR(AND(Recruiting_Data!N406<>"", Recruiting_Data!J406<>"", Recruiting_Data!N406<Recruiting_Data!J406), AND(Recruiting_Data!M406<>"", Recruiting_Data!L406<>"", Recruiting_Data!M406<Recruiting_Data!L406), AND(Recruiting_Data!L406<>"", Recruiting_Data!K406<>"", Recruiting_Data!L406<Recruiting_Data!K406)), TRUE, FALSE))
A407: =IF(Recruiting_Data!A407="", "", Recruiting_Data!A407) | B407: =IF(Recruiting_Data!B407="", "", Recruiting_Data!B407) | C407: =IF(AND(ISNUMBER(Recruiting_Data!N407), ISNUMBER(Recruiting_Data!P407)), Recruiting_Data!N407 - Recruiting_Data!P407, "") | E407: =IF(Recruiting_Data!R407="Open", TODAY() - Recruiting_Data!P407, "") | F407: =IF(E407="", "", IF(E407<=30, "0-30", IF(E407<=60, "31-60", "60+"))) | G407: =IF(A407="", "", IF(COUNTIF(Recruiting_Data!A:A, A407)>1, TRUE, FALSE)) | H407: =IF(A407="", "", IF(OR(AND(Recruiting_Data!N407<>"", Recruiting_Data!J407<>"", Recruiting_Data!N407<Recruiting_Data!J407), AND(Recruiting_Data!M407<>"", Recruiting_Data!L407<>"", Recruiting_Data!M407<Recruiting_Data!L407), AND(Recruiting_Data!L407<>"", Recruiting_Data!K407<>"", Recruiting_Data!L407<Recruiting_Data!K407)), TRUE, FALSE))
A408: =IF(Recruiting_Data!A408="", "", Recruiting_Data!A408) | B408: =IF(Recruiting_Data!B408="", "", Recruiting_Data!B408) | C408: =IF(AND(ISNUMBER(Recruiting_Data!N408), ISNUMBER(Recruiting_Data!P408)), Recruiting_Data!N408 - Recruiting_Data!P408, "") | E408: =IF(Recruiting_Data!R408="Open", TODAY() - Recruiting_Data!P408, "") | F408: =IF(E408="", "", IF(E408<=30, "0-30", IF(E408<=60, "31-60", "60+"))) | G408: =IF(A408="", "", IF(COUNTIF(Recruiting_Data!A:A, A408)>1, TRUE, FALSE)) | H408: =IF(A408="", "", IF(OR(AND(Recruiting_Data!N408<>"", Recruiting_Data!J408<>"", Recruiting_Data!N408<Recruiting_Data!J408), AND(Recruiting_Data!M408<>"", Recruiting_Data!L408<>"", Recruiting_Data!M408<Recruiting_Data!L408), AND(Recruiting_Data!L408<>"", Recruiting_Data!K408<>"", Recruiting_Data!L408<Recruiting_Data!K408)), TRUE, FALSE))
A409: =IF(Recruiting_Data!A409="", "", Recruiting_Data!A409) | B409: =IF(Recruiting_Data!B409="", "", Recruiting_Data!B409) | C409: =IF(AND(ISNUMBER(Recruiting_Data!N409), ISNUMBER(Recruiting_Data!P409)), Recruiting_Data!N409 - Recruiting_Data!P409, "") | E409: =IF(Recruiting_Data!R409="Open", TODAY() - Recruiting_Data!P409, "") | F409: =IF(E409="", "", IF(E409<=30, "0-30", IF(E409<=60, "31-60", "60+"))) | G409: =IF(A409="", "", IF(COUNTIF(Recruiting_Data!A:A, A409)>1, TRUE, FALSE)) | H409: =IF(A409="", "", IF(OR(AND(Recruiting_Data!N409<>"", Recruiting_Data!J409<>"", Recruiting_Data!N409<Recruiting_Data!J409), AND(Recruiting_Data!M409<>"", Recruiting_Data!L409<>"", Recruiting_Data!M409<Recruiting_Data!L409), AND(Recruiting_Data!L409<>"", Recruiting_Data!K409<>"", Recruiting_Data!L409<Recruiting_Data!K409)), TRUE, FALSE))
A410: =IF(Recruiting_Data!A410="", "", Recruiting_Data!A410) | B410: =IF(Recruiting_Data!B410="", "", Recruiting_Data!B410) | C410: =IF(AND(ISNUMBER(Recruiting_Data!N410), ISNUMBER(Recruiting_Data!P410)), Recruiting_Data!N410 - Recruiting_Data!P410, "") | E410: =IF(Recruiting_Data!R410="Open", TODAY() - Recruiting_Data!P410, "") | F410: =IF(E410="", "", IF(E410<=30, "0-30", IF(E410<=60, "31-60", "60+"))) | G410: =IF(A410="", "", IF(COUNTIF(Recruiting_Data!A:A, A410)>1, TRUE, FALSE)) | H410: =IF(A410="", "", IF(OR(AND(Recruiting_Data!N410<>"", Recruiting_Data!J410<>"", Recruiting_Data!N410<Recruiting_Data!J410), AND(Recruiting_Data!M410<>"", Recruiting_Data!L410<>"", Recruiting_Data!M410<Recruiting_Data!L410), AND(Recruiting_Data!L410<>"", Recruiting_Data!K410<>"", Recruiting_Data!L410<Recruiting_Data!K410)), TRUE, FALSE))
A411: =IF(Recruiting_Data!A411="", "", Recruiting_Data!A411) | B411: =IF(Recruiting_Data!B411="", "", Recruiting_Data!B411) | C411: =IF(AND(ISNUMBER(Recruiting_Data!N411), ISNUMBER(Recruiting_Data!P411)), Recruiting_Data!N411 - Recruiting_Data!P411, "") | E411: =IF(Recruiting_Data!R411="Open", TODAY() - Recruiting_Data!P411, "") | F411: =IF(E411="", "", IF(E411<=30, "0-30", IF(E411<=60, "31-60", "60+"))) | G411: =IF(A411="", "", IF(COUNTIF(Recruiting_Data!A:A, A411)>1, TRUE, FALSE)) | H411: =IF(A411="", "", IF(OR(AND(Recruiting_Data!N411<>"", Recruiting_Data!J411<>"", Recruiting_Data!N411<Recruiting_Data!J411), AND(Recruiting_Data!M411<>"", Recruiting_Data!L411<>"", Recruiting_Data!M411<Recruiting_Data!L411), AND(Recruiting_Data!L411<>"", Recruiting_Data!K411<>"", Recruiting_Data!L411<Recruiting_Data!K411)), TRUE, FALSE))
A412: =IF(Recruiting_Data!A412="", "", Recruiting_Data!A412) | B412: =IF(Recruiting_Data!B412="", "", Recruiting_Data!B412) | C412: =IF(AND(ISNUMBER(Recruiting_Data!N412), ISNUMBER(Recruiting_Data!P412)), Recruiting_Data!N412 - Recruiting_Data!P412, "") | E412: =IF(Recruiting_Data!R412="Open", TODAY() - Recruiting_Data!P412, "") | F412: =IF(E412="", "", IF(E412<=30, "0-30", IF(E412<=60, "31-60", "60+"))) | G412: =IF(A412="", "", IF(COUNTIF(Recruiting_Data!A:A, A412)>1, TRUE, FALSE)) | H412: =IF(A412="", "", IF(OR(AND(Recruiting_Data!N412<>"", Recruiting_Data!J412<>"", Recruiting_Data!N412<Recruiting_Data!J412), AND(Recruiting_Data!M412<>"", Recruiting_Data!L412<>"", Recruiting_Data!M412<Recruiting_Data!L412), AND(Recruiting_Data!L412<>"", Recruiting_Data!K412<>"", Recruiting_Data!L412<Recruiting_Data!K412)), TRUE, FALSE))
A413: =IF(Recruiting_Data!A413="", "", Recruiting_Data!A413) | B413: =IF(Recruiting_Data!B413="", "", Recruiting_Data!B413) | C413: =IF(AND(ISNUMBER(Recruiting_Data!N413), ISNUMBER(Recruiting_Data!P413)), Recruiting_Data!N413 - Recruiting_Data!P413, "") | E413: =IF(Recruiting_Data!R413="Open", TODAY() - Recruiting_Data!P413, "") | F413: =IF(E413="", "", IF(E413<=30, "0-30", IF(E413<=60, "31-60", "60+"))) | G413: =IF(A413="", "", IF(COUNTIF(Recruiting_Data!A:A, A413)>1, TRUE, FALSE)) | H413: =IF(A413="", "", IF(OR(AND(Recruiting_Data!N413<>"", Recruiting_Data!J413<>"", Recruiting_Data!N413<Recruiting_Data!J413), AND(Recruiting_Data!M413<>"", Recruiting_Data!L413<>"", Recruiting_Data!M413<Recruiting_Data!L413), AND(Recruiting_Data!L413<>"", Recruiting_Data!K413<>"", Recruiting_Data!L413<Recruiting_Data!K413)), TRUE, FALSE))
... A1000: =IF(Recruiting_Data!A1000="", "", Recruiting_Data!A1000) | B1000: =IF(Recruiting_Data!B1000="", "", Recruiting_Data!B1000) | C1000: =IF(AND(ISNUMBER(Recruiting_Data!N1000), ISNUMBER(Recruiting_Data!P1000)), Recruiting_Data!N1000 - Recruiting_Data!P1000, "") | E1000: =IF(Recruiting_Data!R1000="Open", TODAY() - Recruiting_Data!P1000, "") | F1000: =IF(E1000="", "", IF(E1000<=30, "0-30", IF(E1000<=60, "31-60", "60+"))) | G1000: =IF(A1000="", "", IF(COUNTIF(Recruiting_Data!A:A, A1000)>1, TRUE, FALSE)) | H1000: =IF(A1000="", "", IF(OR(AND(Recruiting_Data!N1000<>"", Recruiting_Data!J1000<>"", Recruiting_Data!N1000<Recruiting_Data!J1000), AND(Recruiting_Data!M1000<>"", Recruiting_Data!L1000<>"", Recruiting_Data!M1000<Recruiting_Data!L1000), AND(Recruiting_Data!L1000<>"", Recruiting_Data!K1000<>"", Recruiting_Data!L1000<Recruiting_Data!K1000)), TRUE, FALSE))

Sheet Pivots

Sheet Exec_Overview
A1: Metric | B1: Value
A2: Open Requisitions | B2: =IFERROR(__xludf.DUMMYFUNCTION("COUNTUNIQUEIFS(Recruiting_Data!B2:B1000, Recruiting_Data!R2:R1000, ""Open"")"),14.0) -> 14
A3: Hires This Week | B3: =COUNTIFS(Recruiting_Data!O:O, "Hired", Recruiting_Data!N:N, ">="&TODAY()-7) -> 0
A4: Average Time To Fill | B4: =AVERAGE(Helper_Calcs!C:C) -> 42.6875
A5: Offer Acceptance Rate | B5: =IF(Funnel!B5=0, 0, Funnel!B6/Funnel!B5) -> 0.55172414
A6: Funnel Conversion Rate | B6: =IF(Funnel!B2=0, 0, Funnel!B6/Funnel!B2) -> 0.16
A7: Headcount vs Plan | B7: =IF((Headcount!B2+Headcount!B3)=0, 0, Headcount!B3 / (Headcount!B2 + Headcount!B3)) -> 0.7254902

Sheet Funnel
A1: Funnel Stage | B1: Count | C1: Conversion Rate
A2: Applied | B2: =COUNTIF(Helper_Calcs!D:D, ">=1") -> 400
A3: Screen | B3: =COUNTIF(Helper_Calcs!D:D, ">=2") -> 237 | C3: =IF(B2=0, 0, B3/B2) -> 0.5925
A4: Onsite | B4: =COUNTIF(Helper_Calcs!D:D, ">=3") -> 176 | C4: =IF(B3=0, 0, B4/B3) -> 0.74261603
A5: Offer | B5: =COUNTIF(Helper_Calcs!D:D, ">=4") -> 116 | C5: =IF(B4=0, 0, B5/B4) -> 0.65909091
A6: Hired | B6: =COUNTIF(Helper_Calcs!D:D, ">=5") -> 64 | C6: =IF(B5=0, 0, B6/B5) -> 0.55172414

Sheet Headcount
A1: Headcount Status | B1: Count
A2: Open Reqs | B2: =IFERROR(__xludf.DUMMYFUNCTION("COUNTUNIQUEIFS(Recruiting_Data!B2:B1000, Recruiting_Data!R2:R1000, ""Open"")"),14.0) -> 14
A3: Filled Reqs | B3: =IFERROR(__xludf.DUMMYFUNCTION("COUNTUNIQUEIFS(Recruiting_Data!B2:B1000, Recruiting_Data!R2:R1000, ""Filled"")"),37.0) -> 37
A4: On Hold Reqs | B4: =IFERROR(__xludf.DUMMYFUNCTION("COUNTUNIQUEIFS(Recruiting_Data!B2:B1000, Recruiting_Data!R2:R1000, ""On Hold"")"),0.0) -> 0
A5: Cancelled Reqs | B5: =IFERROR(__xludf.DUMMYFUNCTION("COUNTUNIQUEIFS(Recruiting_Data!B2:B1000, Recruiting_Data!R2:R1000, ""Cancelled"")"),0.0) -> 0
A8: Aging Buckets | B8: Count
A9: 0-30 | B9: =IFERROR(__xludf.DUMMYFUNCTION("COUNTUNIQUEIFS(Recruiting_Data!B2:B1000, Helper_Calcs!F2:F1000, ""0-30"")"),0.0) -> 0
A10: 31-60 | B10: =IFERROR(__xludf.DUMMYFUNCTION("COUNTUNIQUEIFS(Recruiting_Data!B2:B1000, Helper_Calcs!F2:F1000, ""31-60"")"),0.0) -> 0
A11: 60+ | B11: =IFERROR(__xludf.DUMMYFUNCTION("COUNTUNIQUEIFS(Recruiting_Data!B2:B1000, Helper_Calcs!F2:F1000, ""60+"")"),14.0) -> 14

Sheet Regional
A1: Region | B1: Hires | C1: Open Reqs | D1: Avg TTF
A2: NA | B2: =COUNTIFS(Recruiting_Data!E:E, A2, Recruiting_Data!O:O, "Hired") -> 12 | C2: =COUNTIFS(Recruiting_Data!E:E, A2, Recruiting_Data!R:R, "Open") -> 21 | D2: =IFERROR(AVERAGEIFS(Helper_Calcs!C:C, Recruiting_Data!E:E, A2), "") -> 42.583333
A3: EMEA | B3: =COUNTIFS(Recruiting_Data!E:E, A3, Recruiting_Data!O:O, "Hired") -> 19 | C3: =COUNTIFS(Recruiting_Data!E:E, A3, Recruiting_Data!R:R, "Open") -> 24 | D3: =IFERROR(AVERAGEIFS(Helper_Calcs!C:C, Recruiting_Data!E:E, A3), "") -> 42.684211
A4: APAC | B4: =COUNTIFS(Recruiting_Data!E:E, A4, Recruiting_Data!O:O, "Hired") -> 19 | C4: =COUNTIFS(Recruiting_Data!E:E, A4, Recruiting_Data!R:R, "Open") -> 23 | D4: =IFERROR(AVERAGEIFS(Helper_Calcs!C:C, Recruiting_Data!E:E, A4), "") -> 41.631579
A5: LATAM | B5: =COUNTIFS(Recruiting_Data!E:E, A5, Recruiting_Data!O:O, "Hired") -> 14 | C5: =COUNTIFS(Recruiting_Data!E:E, A5, Recruiting_Data!R:R, "Open") -> 20 | D5: =IFERROR(AVERAGEIFS(Helper_Calcs!C:C, Recruiting_Data!E:E, A5), "") -> 44.214286

Sheet Source
A1: Source Of Hire | B1: Applicants | C1: Hires | D1: Conversion Rate
A2: Referral | B2: =COUNTIF(Recruiting_Data!H:H, A2) -> 89 | C2: =COUNTIFS(Recruiting_Data!H:H, A2, Recruiting_Data!O:O, "Hired") -> 18 | D2: =IF(B2=0, 0, C2/B2) -> 0.20224719
A3: LinkedIn | B3: =COUNTIF(Recruiting_Data!H:H, A3) -> 75 | C3: =COUNTIFS(Recruiting_Data!H:H, A3, Recruiting_Data!O:O, "Hired") -> 14 | D3: =IF(B3=0, 0, C3/B3) -> 0.18666667
A4: Job Board | B4: =COUNTIF(Recruiting_Data!H:H, A4) -> 87 | C4: =COUNTIFS(Recruiting_Data!H:H, A4, Recruiting_Data!O:O, "Hired") -> 12 | D4: =IF(B4=0, 0, C4/B4) -> 0.13793103
A5: Agency | B5: =COUNTIF(Recruiting_Data!H:H, A5) -> 68 | C5: =COUNTIFS(Recruiting_Data!H:H, A5, Recruiting_Data!O:O, "Hired") -> 9 | D5: =IF(B5=0, 0, C5/B5) -> 0.13235294
A6: Internal | B6: =COUNTIF(Recruiting_Data!H:H, A6) -> 0 | C6: =COUNTIFS(Recruiting_Data!H:H, A6, Recruiting_Data!O:O, "Hired") -> 0 | D6: =IF(B6=0, 0, C6/B6) -> 0
A7: University | B7: =COUNTIF(Recruiting_Data!H:H, A7) -> 81 | C7: =COUNTIFS(Recruiting_Data!H:H, A7, Recruiting_Data!O:O, "Hired") -> 11 | D7: =IF(B7=0, 0, C7/B7) -> 0.13580247

Sheet Recruiter
A1: Recruiter | B1: Open Reqs | C1: Hires | D1: Avg TTF | E1: Pipeline Size
A2: A. Rivera | B2: =COUNTIFS(Recruiting_Data!F:F, A2, Recruiting_Data!R:R, "Open") -> 0 | C2: =COUNTIFS(Recruiting_Data!F:F, A2, Recruiting_Data!O:O, "Hired") -> 0 | D2: =IFERROR(AVERAGEIFS(Helper_Calcs!C:C, Recruiting_Data!F:F, A2), "") | E2: =COUNTIF(Recruiting_Data!F:F, A2) -> 0
A3: M. Okafor | B3: =COUNTIFS(Recruiting_Data!F:F, A3, Recruiting_Data!R:R, "Open") -> 0 | C3: =COUNTIFS(Recruiting_Data!F:F, A3, Recruiting_Data!O:O, "Hired") -> 0 | D3: =IFERROR(AVERAGEIFS(Helper_Calcs!C:C, Recruiting_Data!F:F, A3), "") | E3: =COUNTIF(Recruiting_Data!F:F, A3) -> 0
A4: S. Tan | B4: =COUNTIFS(Recruiting_Data!F:F, A4, Recruiting_Data!R:R, "Open") -> 0 | C4: =COUNTIFS(Recruiting_Data!F:F, A4, Recruiting_Data!O:O, "Hired") -> 0 | D4: =IFERROR(AVERAGEIFS(Helper_Calcs!C:C, Recruiting_Data!F:F, A4), "") | E4: =COUNTIF(Recruiting_Data!F:F, A4) -> 0
A5: J. Costa | B5: =COUNTIFS(Recruiting_Data!F:F, A5, Recruiting_Data!R:R, "Open") -> 0 | C5: =COUNTIFS(Recruiting_Data!F:F, A5, Recruiting_Data!O:O, "Hired") -> 0 | D5: =IFERROR(AVERAGEIFS(Helper_Calcs!C:C, Recruiting_Data!F:F, A5), "") | E5: =COUNTIF(Recruiting_Data!F:F, A5) -> 0

Sheet Time_to_Fill
A1: Metric | B1: Value
A2: Average Time To Fill | B2: =AVERAGE(Helper_Calcs!C:C) -> 42.6875
A3: Median Time To Fill | B3: =MEDIAN(Helper_Calcs!C:C) -> 43.5
A5: TTF By Department
A6: Engineering | B6: =IFERROR(AVERAGEIFS(Helper_Calcs!C:C, Recruiting_Data!D:D, A6), "") -> 42.136364
A7: Sales | B7: =IFERROR(AVERAGEIFS(Helper_Calcs!C:C, Recruiting_Data!D:D, A7), "") -> 45.833333
A8: G&A | B8: =IFERROR(AVERAGEIFS(Helper_Calcs!C:C, Recruiting_Data!D:D, A8), "") -> 41.142857
A9: Product | B9: =IFERROR(AVERAGEIFS(Helper_Calcs!C:C, Recruiting_Data!D:D, A9), "") -> 38.6
A11: TTF By Region
A12: NA | B12: =IFERROR(AVERAGEIFS(Helper_Calcs!C:C, Recruiting_Data!E:E, A12), "") -> 42.583333
A13: EMEA | B13: =IFERROR(AVERAGEIFS(Helper_Calcs!C:C, Recruiting_Data!E:E, A13), "") -> 42.684211
A14: APAC | B14: =IFERROR(AVERAGEIFS(Helper_Calcs!C:C, Recruiting_Data!E:E, A14), "") -> 41.631579
A15: LATAM | B15: =IFERROR(AVERAGEIFS(Helper_Calcs!C:C, Recruiting_Data!E:E, A15), "") -> 44.214286

Sheet Data_Quality
A1: Metric | B1: Value
A2: Missing Hire Dates | B2: =COUNTIFS(Recruiting_Data!O:O, "Hired", Recruiting_Data!N:N, "") -> 0
A3: Missing Offer Dates | B3: =COUNTIFS(Recruiting_Data!O:O, "Offer", Recruiting_Data!M:M, "") -> 0
A4: Duplicate Candidates | B4: =COUNTIF(Helper_Calcs!G:G, TRUE) -> 0
A5: Date Logic Errors | B5: =COUNTIF(Helper_Calcs!H:H, TRUE) -> 1
A6: Total Rows | B6: =COUNTA(Recruiting_Data!A:A)-1 -> 400
A7: Data Health Percentage | B7: =IF(B6=0, 1, 1 - ((B2+B3+B4+B5)/B6)) -> 0.9975
A9: Issue Summary Table
A10: Candidate_ID | B10: Issue
A11: =IFERROR(__xludf.DUMMYFUNCTION("LET(candidates, Recruiting_Data!A2:A1000, app, Recruiting_Data!J2:J1000, phone, Recruiting_Data!K2:K1000, onsite, Recruiting_Data!L2:L1000, offer, Recruiting_Data!M2:M1000, hire, Recruiting_Data!N2:N1000, stage, Recruiting_Data!O2:O1000, issues, MAP(candi"&"dates, app, phone, onsite, offer, hire, stage, LAMBDA(c, j, k, l, m, n, o, IF(c="""", """", IF(AND(o=""Hired"", n=""""), ""Missing Hire_Date for Hired candidate"", IF(AND(o=""Offer"", m=""""), ""Missing Offer_Date for Offer stage candidate"", IF(OR(AND(k<"&">"""", j<>"""", k<j), AND(l<>"""", j<>"""", l<j), AND(l<>"""", k<>"""", l<k), AND(m<>"""", j<>"""", m<j), AND(m<>"""", k<>"""", m<k), AND(m<>"""", l<>"""", m<l), AND(n<>"""", j<>"""", n<j), AND(n<>"""", k<>"""", n<k), AND(n<>"""", l<>"""", n<l), AND(n<>"""&""", m<>"""", n<m)), ""Dates out of order"", """")))))), IFERROR(FILTER(HSTACK(candidates, issues), issues<>""""), {""No issues found"", """"}))"),"C-10264") -> C-10264 | B11: =IFERROR(__xludf.DUMMYFUNCTION("""COMPUTED_VALUE"""),"Dates out of order") -> Dates out of order
A12: =IFERROR(__xludf.DUMMYFUNCTION("""COMPUTED_VALUE"""),"C-10358") -> C-10358 | B12: =IFERROR(__xludf.DUMMYFUNCTION("""COMPUTED_VALUE"""),"Dates out of order") -> Dates out of order

Sheet Weekly_Snapshots
A1: Week_Of | B1: Open_Reqs | C1: Hires | D1: Avg_Time_To_Fill | E1: Offer_Acceptance | F1: Funnel_Conversion | G1: Headcount_vs_Plan
A2: 46132 | B2: 300 | C2: 5 | D2: 58 | E2: 0.82 | F2: 0.14 | G2: 0.1
A3: 46139 | B3: 305 | C3: 7 | D3: 56 | E3: 0.85 | F3: 0.15 | G3: 0.11
A4: 46146 | B4: 310 | C4: 6 | D4: 54 | E4: 0.84 | F4: 0.14 | G4: 0.12
A5: 46153 | B5: 315 | C5: 8 | D5: 52 | E5: 0.86 | F5: 0.15 | G5: 0.13
A6: 46160 | B6: 320 | C6: 9 | D6: 50 | E6: 0.88 | F6: 0.16 | G6: 0.14
A7: 46167 | B7: 325 | C7: 7 | D7: 48 | E7: 0.87 | F7: 0.15 | G7: 0.15
A8: 46174 | B8: 330 | C8: 10 | D8: 46 | E8: 0.89 | F8: 0.16 | G8: 0.15
A9: 46181 | B9: 336 | C9: 23 | D9: 43 | E9: 0.552 | F9: 0.16 | G9: 0.16
A10: 46183.681 | B10: 14 | C10: 23 | D10: 42.6875 | E10: 0.55172414 | F10: 0.16 | G10: 0.7254902
A11: 46183.683 | B11: 14 | C11: 23 | D11: 42.6875 | E11: 0.55172414 | F11: 0.16 | G11: 0.7254902
A12: 46184.446 | B12: 14 | C12: 21 | D12: 42.6875 | E12: 0.55172414 | F12: 0.16 | G12: 0.7254902
A13: 46188.329 | B13: 14 | C13: 20 | D13: 42.6875 | E13: 0.55172414 | F13: 0.16 | G13: 0.7254902
... A26: 46279.329 | B26: 14 | C26: 0 | D26: 42.6875 | E26: 0.55172414 | F26: 0.16 | G26: 0.7254902

Sheet AI_Output
A1: HEADLINE The main takeaway is that we have not made any hires this week, and our average time to fill a position is approximately 43 days. WHAT CHANGED There were no changes in the number of open requisitions, hires, or time to fill from last week, with no hires and no movement in time to fill. RISKS Our headcount is currently at 72.5% of plan, which may indicate a risk in meeting our hiring targets, and our offer acceptance rate of 55.2% may also be a concern. OPPORTUNITIES Our funnel conversion rate of 16.0% presents an opportunity to improve our hiring process and increase the number of candidates moving through the funnel to become hires.

Sheet Config
A1: Region | B1: Current Stage | C1: Headcount Status | D1: Candidate Type | E1: Source Of Hire
A2: NA | B2: Applied | C2: Open | D2: External | E2: Referral
A3: EMEA | B3: Screen | C3: Filled | D3: Internal | E3: LinkedIn
A4: APAC | B4: Onsite | C4: On Hold | D4: Referral | E4: Job Board
A5: LATAM | B5: Offer | C5: Cancelled | D5: New Grad | E5: Agency
B6: Hired | E6: Internal
B7: Rejected | E7: University
B8: Withdrawn

Sheet Logs
A1: Timestamp | B1: Message | C1: Status
A2: 46183.727 | B2: FAILED: GROQ_API_KEY not set in Script Properties
A3: 46183.727 | B3: FAILED: GROQ_API_KEY not set in Script Properties
A4: 46183.729 | B4: FAILED: GROQ_API_KEY not set in Script Properties
A5: 46183.734 | B5: FAILED: GROQ_API_KEY not set in Script Properties
A6: 46183.741 | B6: SUCCESS: https://docs.google.com/presentation/d/12zFvpRBC_SNm5YSE7_PdMAICt-F6SnL_5bb4sF3SLY8/edit?usp=drivesdk
A7: 46183.751 | B7: SUCCESS: https://docs.google.com/presentation/d/1Jw38XcJQm789TjsqCVyGyRcHfbfDAbx7a63OmJfAaow/edit?usp=drivesdk
A8: 46184.447 | B8: SUCCESS: https://docs.google.com/presentation/d/1ELYUV8x6XaJSB4odKTemYOrwVf31Ee0084ITcb40Fus/edit?usp=drivesdk
A9: 46188.329 | B9: SUCCESS: https://docs.google.com/presentation/d/1gFQwxIDBwxPNJ7s2uyUN0-FGk-iHNGAVhY5_YVE0-Hw/edit?usp=drivesdk
A10: 46195.329 | B10: SUCCESS: https://docs.google.com/presentation/d/1bYVtEbOj31iyDAHA1qUh6vx1ll-3Hz1qnr7UexlFEAE/edit?usp=drivesdk
A11: 46202.329 | B11: SUCCESS: https://docs.google.com/presentation/d/1wADLyT8zBTWbuAruTnyfoCUrYueP59gLLeuCaJL5QP4/edit?usp=drivesdk
A12: 46209.329 | B12: SUCCESS: https://docs.google.com/presentation/d/17Fp350S_yDTGH4hhu3xM_CfhZbiMWp4E2K1zjzjvTWA/edit?usp=drivesdk
A13: 46216.329 | B13: SUCCESS: https://docs.google.com/presentation/d/1v0Qu-IgHo6w3mJfJAuJt6XBIH-a33ALRaxzWTlNHnKo/edit?usp=drivesdk
... A22: 46279.329 | B22: FAILED: Groq error: {"error":{"message":"The model `llama-3.3-70b-versatile` does not exist or you do not have access to it.","type":"invalid_request_error","code":"model_not_found"}}
